Workbook

Sheet 1
A2: Moneda: Euro | D2: 01 EDUCATION
A3: PAGA TOTAL
A4: DEL 01/01/26 AL 31/01/26 | D4: 000170 | E4: 000183 | F4: 000222
A5: Empresa: 4008-DSD PLANNING CENTER S.L. NIF: B86563285 | D5: BISCEGLI | E5: PETERSEN | F5: PETERSEN
D6: FILHO | E6: HERRERA | F6: HERRERA
D7: CARLOS | E7: JOHN MICHAEL | F7: ERIK STEWARD
A9: CONCEPTO
B11: 1 | C11: Salario Base | D11: 4000 | E11: 1215.24 | F11: 1215.24
B12: 3 | C12: Mejora Voluntaria | D12: 1028.9 | E12: 777.79 | F12: 444.46
B13: 123 | C13: Prorrata PP. Extras | D13: 666.66 | E13: 202.54 | F13: 202.54
B14: 275 | C14: Teletrabajo | D14: 15 | E14: 15 | F14: 15
B15: 276 | C15: Descuento Comida Flex | E15: -54.16
B16: 337 | C16: Comida Flex (Exenta) | E16: 54.16
B17: 398 | C17: Plus Transporte | D17: 137.76 | E17: 137.76 | F17: 137.76
A19: TOTAL BRUTO | D19: =SUM(D11:D18) -> 5848.32 | E19: =SUM(E11:E18) -> 2348.33 | F19: =SUM(F11:F18) -> 2015
B21: 789 | C21: Dcto.Conceptos en Especi | E21: 54.16
B22: 995 | C22: COTIZACION CONT.COMUNES | D22: 248.88 | E22: 113.89 | F22: 97.73
B23: 996 | C23: COTIZACION FORMACION PRO | D23: 5.1 | E23: 2.35 | F23: 2.02
B24: 997 | C24: COTIZACION DESEMPLEO | D24: 79.07 | E24: 36.4 | F24: 31.23
B25: 999 | C25: TRIBUTACION I.R.P.F. | D25: 1574.95 | E25: 359.5 | F25: 275.05
A27: TOTAL DEDUCCIONES | D27: =SUM(D20:D26) -> 1908 | E27: =SUM(E20:E26) -> 566.3 | F27: =SUM(F20:F26) -> 406.03
A29: TOTAL LIQUIDO | D29: =(D19-D27) -> 3940.32 | E29: =(E19-E27) -> 1782.03 | F29: =(F19-F27) -> 1608.97
A30: PRORRATA PAGAS EXTRAS | D30: 0 | E30: 0 | F30: 0
A31: SEGURIDAD SOCIAL EMPRESA | D31: 1647.39 | E31: 755 | F31: 647.84
A32: SEGURIDAD SOCIAL TRABAJADOR | D32: 333.05 | E32: 152.64 | F32: 130.98
A33: SEGURIDAD SOCIAL TOTAL | D33: 1980.44 | E33: 907.64 | F33: 778.82
A34: COSTE COLAB. VOLUNTARIA | D34: 0 | E34: 0 | F34: 0
A35: APORTAC. SERVICIOS COMUNES | D35: 0 | E35: 0 | F35: 0
A36: COSTE EMPRESA | D36: =D19+D31 -> 7495.71 | E36: =E19+E31 -> 3103.33 | F36: =F19+F31 -> 2662.84
A37: BASE CONTINGENCIAS COMUNES | D37: 5101.2 | E37: 2348.33 | F37: 2015
A38: BASE ACCIDENTES | D38: 5101.2 | E38: 2348.33 | F38: 2015
A39: BASE I.R.P.F. DINERARIA | D39: 5848.32 | E39: 2294.17 | F39: 2015
A40: BASE I.R.P.F. ESPECIES | D40: 0 | E40: 0 | F40: 0
A41: BASE I.R.P.F. IRREGULAR | D41: 0 | E41: 0 | F41: 0
A42: HORAS EXTRAS NORMALES | D42: 0 | E42: 0 | F42: 0
A43: HORAS EXTRAS ESTRUCTURALES | D43: 0 | E43: 0 | F43: 0
A44: HORAS PRESENCIA | D44: 160 | E44: 160 | F44: 160
A45: DIAS DESEMPLEO PARCIAL | D45: 0 | E45: 0 | F45: 0
A46: IMPORTE BONIFICACION | D46: 0 | E46: 0 | F46: 0
A47: DIAS COTIZADOS | D47: 30 | E47: 30 | F47: 30

Sheet 2
A2: Moneda: Euro | D2: 01 EDUCATION
A3: PAGA TOTAL
A4: DEL 01/01/26 AL 31/01/26 | D4: TOTAL
A5: Empresa: 4008-DSD PLANNING CENTER S.L. NIF: B86563285 | D5: EDUCATION
A9: CONCEPTO
B11: 1 | C11: Salario Base | D11: =SUM('1'!$D$11:$G$11) -> 6430.48
B12: 3 | C12: Mejora Voluntaria | D12: =SUM('1'!$D$12:$G$12) -> 2251.15
B13: 123 | C13: Prorrata PP. Extras | D13: =SUM('1'!$D$13:$G$13) -> 1071.74
B14: 275 | C14: Teletrabajo | D14: =SUM('1'!$D$14:$G$14) -> 45
B15: 276 | C15: Descuento Comida Flex | D15: =SUM('1'!$D$15:$G$15) -> -54.16
B16: 337 | C16: Comida Flex (Exenta) | D16: =SUM('1'!$D$16:$G$16) -> 54.16
B17: 398 | C17: Plus Transporte | D17: =SUM('1'!$D$17:$G$17) -> 413.28
A19: TOTAL BRUTO | D19: =SUM('1'!$D$19:$G$19) -> 10211.65
B21: 789 | C21: Dcto.Conceptos en Especi | D21: =SUM('1'!$D$21:$G$21) -> 54.16
B22: 995 | C22: COTIZACION CONT.COMUNES | D22: =SUM('1'!$D$22:$G$22) -> 460.5
B23: 996 | C23: COTIZACION FORMACION PRO | D23: =SUM('1'!$D$23:$G$23) -> 9.47
B24: 997 | C24: COTIZACION DESEMPLEO | D24: =SUM('1'!$D$24:$G$24) -> 146.7
B25: 999 | C25: TRIBUTACION I.R.P.F. | D25: =SUM('1'!$D$25:$G$25) -> 2209.5
A27: TOTAL DEDUCCIONES | D27: =SUM('1'!$D$27:$G$27) -> 2880.33
A29: TOTAL LIQUIDO | D29: =SUM('1'!$D$29:$G$29) -> 7331.32
A30: PRORRATA PAGAS EXTRAS | D30: =SUM('1'!$D$30:$G$30) -> 0
A31: SEGURIDAD SOCIAL EMPRESA | D31: =SUM('1'!$D$31:$G$31) -> 3050.23
A32: SEGURIDAD SOCIAL TRABAJADOR | D32: =SUM('1'!$D$32:$G$32) -> 616.67
A33: SEGURIDAD SOCIAL TOTAL | D33: =SUM('1'!$D$33:$G$33) -> 3666.9
A34: COSTE COLAB. VOLUNTARIA | D34: =SUM('1'!$D$34:$G$34) -> 0
A35: APORTAC. SERVICIOS COMUNES | D35: =SUM('1'!$D$35:$G$35) -> 0
A36: COSTE EMPRESA | D36: =SUM('1'!$D$36:$G$36) -> 13261.88
A37: BASE CONTINGENCIAS COMUNES | D37: =SUM('1'!$D$37:$G$37) -> 9464.53
A38: BASE ACCIDENTES | D38: =SUM('1'!$D$38:$G$38) -> 9464.53
A39: BASE I.R.P.F. DINERARIA | D39: =SUM('1'!$D$39:$G$39) -> 10157.49
A40: BASE I.R.P.F. ESPECIES | D40: =SUM('1'!$D$40:$G$40) -> 0
A41: BASE I.R.P.F. IRREGULAR | D41: =SUM('1'!$D$41:$G$41) -> 0
A42: HORAS EXTRAS NORMALES | D42: =SUM('1'!$D$42:$G$42) -> 0
A43: HORAS EXTRAS ESTRUCTURALES | D43: =SUM('1'!$D$43:$G$43) -> 0
A44: HORAS PRESENCIA | D44: =SUM('1'!$D$44:$G$44) -> 480
A45: DIAS DESEMPLEO PARCIAL | D45: =SUM('1'!$D$45:$G$45) -> 0
A46: IMPORTE BONIFICACION | D46: =SUM('1'!$D$46:$G$46) -> 0
A47: DIAS COTIZADOS | D47: =SUM('1'!$D$47:$G$47) -> 90
A48: TOTAL TRABAJADORES | D48: 3

Sheet 3
A2: Moneda: Euro | D2: 02 MARKETING
A3: PAGA TOTAL
A4: DEL 01/01/26 AL 31/01/26 | D4: 000073 | E4: 000085 | F4: 000123 | G4: 000124 | H4: 000199 | I4: 000209
A5: Empresa: 4008-DSD PLANNING CENTER S.L. NIF: B86563285 | D5: MASON | E5: CASTELLANOS | F5: DE ARBELOA | G5: MACDONALD | H5: RUBIO | I5: SANCHEZ
D6: DAISY | E6: WEIDLICH | F6: RACHADELL | G6: MARITA | H6: OLIVEROS | I6: GARCIA
E7: CATERINA | F7: LUKEN | H7: GISSEL PAOLA | I7: MARIO
A9: CONCEPTO
B11: 1 | C11: Salario Base | D11: 2500 | E11: 1399.21 | F11: 5000 | G11: 3693.39 | H11: 1312.81 | I11: 1215.24
B12: 3 | C12: Mejora Voluntaria | D12: 695.57 | E12: 729.82 | F12: 1695.57 | G12: 59.66 | H12: 1080.62 | I12: 944.45
B13: 123 | C13: Prorrata PP. Extras | D13: 416.66 | E13: 233.2 | F13: 833.34 | G13: 615.56 | H13: 218.8 | I13: 202.54
B14: 181 | C14: Plus Cumplimiento Objeti | E14: 1024.3
B15: 275 | C15: Teletrabajo | D15: 15 | E15: 15 | F15: 15 | G15: 15 | H15: 15 | I15: 15
B16: 276 | C16: Descuento Comida Flex | E16: -220 | G16: -220 | H16: -214.35 | I16: -220
B17: 277 | C17: Descuento Transp Flex | E17: -133.95 | G17: -136.36 | H17: -38.2 | I17: -7.3
B18: 282 | C18: Vehículo Empresa | G18: 458.82
B19: 337 | C19: Comida Flex (Exenta) | E19: 220 | G19: 220 | H19: 214.35 | I19: 220
B20: 339 | C20: Comida B. Social (Exent | D20: 215.34 | F20: 220
B21: 343 | C21: Transporte Flex (Exento) | E21: 133.95 | G21: 136.36 | H21: 38.2 | I21: 7.3
B22: 345 | C22: Transporte B.S (Exento) | D22: 21.9 | F22: 136.36
B23: 353 | C23: Seguro Médico B.S.(Exent | D23: 41.67 | F23: 125.01 | G23: 41.67
B24: 356 | C24: Seguro Médico B.S. (No E | D24: 23.09 | F24: 69.27 | G24: 23.09
B25: 398 | C25: Plus Transporte | D25: 137.76 | E25: 137.76 | F25: 137.76 | G25: 137.76 | H25: 137.76 | I25: 137.76
B26: 988 | C26: Imp.Ingr. a Cta. Esp. Cg | D26: 4.86 | F26: 21.74 | G26: 113.15
A28: TOTAL BRUTO | D28: =SUM(D11:D27) -> 4071.85 | E28: =SUM(E11:E27) -> 3539.29 | F28: =SUM(F11:F27) -> 8254.05 | G28: =SUM(G11:G27) -> 5158.1 | H28: =SUM(H11:H27) -> 2764.99 | I28: =SUM(I11:I27) -> 2514.99
B30: 768 | C30: Anticipo Paternidad | F30: 1119.4
B31: 789 | C31: Dcto.Conceptos en Especi | D31: 302 | E31: 353.95 | F31: 550.64 | G31: 879.94 | H31: 252.55 | I31: 227.3
B32: 989 | C32: Imp.Ingr.a Cta.Valores E | D32: 4.86 | F32: 21.74 | G32: 113.15
B33: 995 | C33: COTIZACION CONT.COMUNES | D33: 197.25 | E33: 171.66 | F33: 254.06 | G33: 244.68 | H33: 134.1 | I33: 121.97
B34: 996 | C34: COTIZACION FORMACION PRO | D34: 4.07 | E34: 3.54 | F34: 5.1 | G34: 5.04 | H34: 2.76 | I34: 2.51
B35: 997 | C35: COTIZACION DESEMPLEO | D35: 63.04 | E35: 54.86 | F35: 79.07 | G35: 78.2 | H35: 42.86 | I35: 38.98
B36: 999 | C36: TRIBUTACION I.R.P.F. | D36: 792.53 | E36: 639.3 | F36: 2411.28 | G36: 977.94 | H36: 436.66 | I36: 373.35
A38: TOTAL DEDUCCIONES | D38: =SUM(D29:D37) -> 1363.75 | E38: =SUM(E29:E37) -> 1223.31 | F38: =SUM(F29:F37) -> 4441.29 | G38: =SUM(G29:G37) -> 2298.95 | H38: =SUM(H29:H37) -> 868.93 | I38: =SUM(I29:I37) -> 764.11
A40: TOTAL LIQUIDO | D40: =(D28-D38) -> 2708.1 | E40: =(E28-E38) -> 2315.98 | F40: =(F28-F38) -> 3812.76 | G40: =(G28-G38) -> 2859.15 | H40: =(H28-H38) -> 1896.06 | I40: =(I28-I38) -> 1750.88
A41: PRORRATA PAGAS EXTRAS | D41: 0 | E41: 0 | F41: 0 | G41: 0 | H41: 0 | I41: 0
A42: SEGURIDAD SOCIAL EMPRESA | D42: 1307.53 | E42: 1137.88 | F42: 1673.24 | G42: 1621.94 | H42: 888.93 | I42: 808.57
A43: SEGURIDAD SOCIAL TRABAJADOR | D43: 264.36 | E43: 230.06 | F43: 338.23 | G43: 327.92 | H43: 179.72 | I43: 163.46
A44: SEGURIDAD SOCIAL TOTAL | D44: 1571.89 | E44: 1367.94 | F44: 2011.47 | G44: 1949.86 | H44: 1068.65 | I44: 972.03
A45: COSTE COLAB. VOLUNTARIA | D45: 0 | E45: 0 | F45: 0 | G45: 0 | H45: 0 | I45: 0
A46: APORTAC. SERVICIOS COMUNES | D46: 0 | E46: 0 | F46: 0 | G46: 0 | H46: 0 | I46: 0
A47: COSTE EMPRESA | D47: =D28+D42 -> 5379.38 | E47: =E28+E42 -> 4677.17 | F47: =F28+F42 -> 9927.29 | G47: =G28+G42 -> 6780.04 | H47: =H28+H42 -> 3653.92 | I47: =I28+I42 -> 3323.56
...

Sheet 4
A2: Moneda: Euro | D2: 02 MARKETING
A3: PAGA TOTAL
A4: DEL 01/01/26 AL 31/01/26 | D4: TOTAL
A5: Empresa: 4008-DSD PLANNING CENTER S.L. NIF: B86563285 | D5: MARKETING
A9: CONCEPTO
B11: 1 | C11: Salario Base | D11: =SUM('3'!$D$11:$J$11) -> 15120.65
B12: 3 | C12: Mejora Voluntaria | D12: =SUM('3'!$D$12:$J$12) -> 5205.69
B13: 123 | C13: Prorrata PP. Extras | D13: =SUM('3'!$D$13:$J$13) -> 2520.1
B14: 181 | C14: Plus Cumplimiento Objeti | D14: =SUM('3'!$D$14:$J$14) -> 1024.3
B15: 275 | C15: Teletrabajo | D15: =SUM('3'!$D$15:$J$15) -> 90
B16: 276 | C16: Descuento Comida Flex | D16: =SUM('3'!$D$16:$J$16) -> -874.35
B17: 277 | C17: Descuento Transp Flex | D17: =SUM('3'!$D$17:$J$17) -> -315.81
B18: 282 | C18: Vehículo Empresa | D18: =SUM('3'!$D$18:$J$18) -> 458.82
B19: 337 | C19: Comida Flex (Exenta) | D19: =SUM('3'!$D$19:$J$19) -> 874.35
B20: 339 | C20: Comida B. Social (Exent | D20: =SUM('3'!$D$20:$J$20) -> 435.34
B21: 343 | C21: Transporte Flex (Exento) | D21: =SUM('3'!$D$21:$J$21) -> 315.81
B22: 345 | C22: Transporte B.S (Exento) | D22: =SUM('3'!$D$22:$J$22) -> 158.26
B23: 353 | C23: Seguro Médico B.S.(Exent | D23: =SUM('3'!$D$23:$J$23) -> 208.35
B24: 356 | C24: Seguro Médico B.S. (No E | D24: =SUM('3'!$D$24:$J$24) -> 115.45
B25: 398 | C25: Plus Transporte | D25: =SUM('3'!$D$25:$J$25) -> 826.56
B26: 988 | C26: Imp.Ingr. a Cta. Esp. Cg | D26: =SUM('3'!$D$26:$J$26) -> 139.75
A28: TOTAL BRUTO | D28: =SUM('3'!$D$28:$J$28) -> 26303.27
B30: 768 | C30: Anticipo Paternidad | D30: =SUM('3'!$D$30:$J$30) -> 1119.4
B31: 789 | C31: Dcto.Conceptos en Especi | D31: =SUM('3'!$D$31:$J$31) -> 2566.38
B32: 989 | C32: Imp.Ingr.a Cta.Valores E | D32: =SUM('3'!$D$32:$J$32) -> 139.75
B33: 995 | C33: COTIZACION CONT.COMUNES | D33: =SUM('3'!$D$33:$J$33) -> 1123.72
B34: 996 | C34: COTIZACION FORMACION PRO | D34: =SUM('3'!$D$34:$J$34) -> 23.02
B35: 997 | C35: COTIZACION DESEMPLEO | D35: =SUM('3'!$D$35:$J$35) -> 357.01
B36: 999 | C36: TRIBUTACION I.R.P.F. | D36: =SUM('3'!$D$36:$J$36) -> 5631.06
A38: TOTAL DEDUCCIONES | D38: =SUM('3'!$D$38:$J$38) -> 10960.34
A40: TOTAL LIQUIDO | D40: =SUM('3'!$D$40:$J$40) -> 15342.93
A41: PRORRATA PAGAS EXTRAS | D41: =SUM('3'!$D$41:$J$41) -> 0
A42: SEGURIDAD SOCIAL EMPRESA | D42: =SUM('3'!$D$42:$J$42) -> 7438.09
A43: SEGURIDAD SOCIAL TRABAJADOR | D43: =SUM('3'!$D$43:$J$43) -> 1503.75
A44: SEGURIDAD SOCIAL TOTAL | D44: =SUM('3'!$D$44:$J$44) -> 8941.84
A45: COSTE COLAB. VOLUNTARIA | D45: =SUM('3'!$D$45:$J$45) -> 0
A46: APORTAC. SERVICIOS COMUNES | D46: =SUM('3'!$D$46:$J$46) -> 0
A47: COSTE EMPRESA | D47: =SUM('3'!$D$47:$J$47) -> 33741.36
A48: BASE CONTINGENCIAS COMUNES | D48: =SUM('3'!$D$48:$J$48) -> 23032.41
A49: BASE ACCIDENTES | D49: =SUM('3'!$D$49:$J$49) -> 23032.41
...

Sheet 5
A2: Moneda: Euro | D2: 03 PLANNING CENTER
A3: PAGA TOTAL
A4: DEL 01/01/26 AL 31/01/26 | D4: 000016 | E4: 000021 | F4: 000022 | G4: 000024 | H4: 000027 | I4: 000028 | J4: 000039 | K4: 000044 | L4: 000055 | M4: 000065 | N4: 000067 | O4: 000068 | P4: 000094 | Q4: 000095 | R4: 000097 | S4: 000114 | T4: 000125 | U4: 000131 | V4: 000132 | W4: 000133 | X4: 000134 | Y4: 000136 | Z4: 000145 | AA4: 000147 | AB4: 000152 | AC4: 000155 | AD4: 000156 | AE4: 000165 | AF4: 000166 | AG4: 000168 | AH4: 000174 | AI4: 000176 | AJ4: 000177 | AK4: 000184 | AL4: 000189 | AM4: 000190 | AN4: 000194 | AO4: 000202 | AP4: 000204 | AQ4: 000208 | AR4: 000210 | AS4: 000211 | AT4: 000212 | AU4: 000214 | AV4: 000218 | AW4: 000223 | AX4: 000227
A5: Empresa: 4008-DSD PLANNING CENTER S.L. NIF: B86563285 | D5: SANCHEZ | E5: LABANDERA | F5: PADILLA | G5: JIMENEZ | H5: COIRAZZA | I5: AMARANTE | J5: GOMEZ | K5: PICON | L5: DOS | M5: RAMOS | N5: MOLINA | O5: CAÑIZARES | P5: PERAZA | Q5: HERNANDEZ | R5: LOPEZ | S5: FERNANDES | T5: PINTO | U5: BRETON | V5: MASTROMATTEO | W5: DALE | X5: QUINTANA | Y5: MOLERO | Z5: GOMEZ | AA5: LABANDERA | AB5: ZABLOTZKY | AC5: HARTE | AD5: GUTIERREZ | AE5: OPALINSKI | AF5: WATZKO | AG5: SERRANO | AH5: LOZANO | AI5: GONZALEZ | AJ5: KUTT | AK5: NKOGO | AL5: GARCIA | AM5: PRIETO | AN5: CARRERA | AO5: DOS | AP5: LEIVA | AQ5: MARIN | AR5: CASTRILLON | AS5: LOPEZ | AT5: LIRIANO | AU5: TOMA | AV5: MATTHEWS | AW5: VASQUEZ | AX5: BASTIDAS
D6: CALEYA | E6: FAJARDO | F6: CALI | G6: SALAZAR | H6: LAURA-ELISA | I6: COACHMAN | J6: PULIDO | K6: CALZADA | L6: RAMOS | M6: AREVALO | N6: MUÑOZ | O6: SORIANO | P6: LABRADOR | Q6: DIAZ | R6: SAN JUAN | S6: ABREU | T6: RAMOS | U6: PEREZ | V6: MANAURE | W6: PARRA | X6: GODOY | Y6: DONAIRE | Z6: JOSE | AA6: FAJARDO | AB6: LUISINA | AC6: LOURDES | AD6: SILVA | AE6: RAUCHMAN | AF6: DE MELO | AG6: MAJANO | AH6: ARCE | AI6: BAUTISTA | AJ6: SANTOS | AK6: NCHAMA | AL6: LAVELLI | AM6: MARTINEZ | AN6: RODRIGUEZ | AO6: SANTOS | AP6: RODRIGUEZ | AQ6: SEBASTIAN | AR6: RUIZ | AS6: RODRIGUEZ | AT6: AMARANTE | AU6: ANA | AV6: DANIELLE | AW6: VERGARA | AX6: YAGUANA
D7: ANGEL-LUIS | E7: LORENA-CRIST | F7: VERONICA | G7: EDORTA | I7: JOHN WILLIAM | J7: MANUEL | K7: PAULA | L7: KATHY CAROLI | M7: JESUS MARIA | N7: DAVID | O7: PATRICIA | P7: EDUARDO-JOSE | Q7: MARIANA-RAQU | R7: ELISABET | S7: MERY HELEN | T7: DANIEL SOUZA | U7: JOANNY SCARL | V7: MARIA FERNAN | W7: FABIANA DEL | X7: ORIANA ISABE | Y7: VICTOR | Z7: ESTEBAN | AA7: ARIANNA | AB7: MARIEL | AC7: MARIA BRIGID | AD7: VICTORIA EUG | AE7: ALEJANDRA | AF7: CAROLINA | AG7: RICARDO ALFR | AH7: STEPHANY | AI7: IVAN | AJ7: LEILI | AK7: JOSE DANIEL | AL7: MARIANNA | AM7: DANIEL | AN7: RICHARD EDWI | AO7: DONATO CRIST | AP7: ROBERTO ALEJ | AR7: NORA | AS7: AMANDA | AT7: DIANNY ANDRE | AU7: MARIA | AV7: ANITA | AW7: ROBERTO JR | AX7: MARIA JOSE
A9: CONCEPTO
B11: 1 | C11: Salario Base | D11: 1666.67 | E11: 2000 | F11: 2000 | G11: 1400 | H11: 2000 | I11: 5000 | J11: 2000 | K11: 1154.79 | L11: 2000 | M11: 2500 | N11: 2000 | O11: 1215.24 | P11: 1399.21 | Q11: 2500 | R11: 1122 | S11: 1154.79 | T11: 4000 | V11: 1154.79 | W11: 1500 | X11: 1500 | Z11: 1154.79 | AA11: 1154.79 | AB11: 1154.79 | AC11: 1154.79 | AD11: 1154.79 | AE11: 1312.8 | AF11: 1312.8 | AG11: 1215.24 | AH11: 1215.24 | AI11: 1215.24 | AJ11: 1215.24 | AK11: 864 | AL11: 1215.24 | AM11: 1500 | AN11: 1080 | AO11: 1080 | AP11: 1215.24 | AQ11: 1215.24 | AR11: 1167.63 | AS11: 1215.24 | AU11: 1167.63 | AV11: 1215.24 | AW11: 1215.24 | AX11: 486.1
B12: 3 | C12: Mejora Voluntaria | D12: 1065.76 | E12: 862.24 | F12: 528.91 | G12: 1062.23 | H12: 28.91 | I12: 2201.55 | J12: 278.91 | K12: 1603.01 | L12: 866.94 | M12: 2945.58 | N12: 28.91 | O12: 777.79 | P12: 979.83 | Q12: 612.24 | R12: 1053.24 | S12: 848.32 | T12: 1695.57 | V12: 1014.99 | W12: 862.24 | X12: 862.24 | Z12: 1014.99 | AA12: 848.32 | AB12: 1264.99 | AC12: 1014.99 | AD12: 848.32 | AE12: 330.63 | AF12: 913.97 | AG12: 1027.79 | AH12: 444.46 | AI12: 444.46 | AJ12: 444.46 | AK12: 481.79 | AL12: 444.46 | AM12: 945.57 | AN12: 768.91 | AO12: 352.24 | AP12: 194.45 | AQ12: 777.79 | AR12: 250.01 | AS12: 194.45 | AU12: 250.01 | AV12: 194.46 | AW12: 194.46 | AX12: 77.78
B13: 8 | C13: Plus Actividad | AV13: 8.13
B14: 51 | C14: Complemento Especialidad | I14: 1100
B15: 53 | C15: Plus Nocturnidad | AE15: 200 | AP15: 450.01 | AW15: 175
B16: 63 | C16: Complemento de puesto te | AG16: 258.3
B17: 65 | C17: Complemento Puesto | M17: 666.66
B18: 123 | C18: Prorrata PP. Extras | D18: 288.88 | E18: 333.34 | F18: 333.34 | G18: 233.34 | H18: 333.34 | I18: 833.34 | J18: 333.34 | K18: 192.46 | L18: 333.34 | M18: 416.66 | N18: 333.34 | O18: 202.54 | P18: 233.2 | Q18: 416.66 | R18: 187 | S18: 192.46 | T18: 666.66 | V18: 192.46 | W18: 250 | X18: 250 | Z18: 192.46 | AA18: 192.46 | AB18: 192.46 | AC18: 192.46 | AD18: 192.46 | AE18: 218.8 | AF18: 218.8 | AG18: 202.54 | AH18: 202.54 | AI18: 202.54 | AJ18: 202.54 | AK18: 150 | AL18: 202.54 | AM18: 250 | AN18: 180 | AO18: 180 | AP18: 202.54 | AQ18: 202.54 | AR18: 194.6 | AS18: 202.54 | AU18: 194.6 | AV18: 202.54 | AW18: 202.54 | AX18: 87.76
B19: 181 | C19: Plus Cumplimiento Objeti | AL19: 699
B20: 275 | C20: Teletrabajo | D20: 15 | F20: 15 | G20: 15 | H20: 15 | I20: 15 | J20: 15 | K20: 15 | L20: 15 | M20: 15 | N20: 15 | O20: 15 | P20: 15 | Q20: 15 | S20: 15 | T20: 15 | V20: 15 | W20: 15 | X20: 15 | Y20: 15 | Z20: 15 | AA20: 15 | AB20: 15 | AC20: 15 | AD20: 15 | AE20: 15 | AF20: 15 | AG20: 15 | AH20: 15 | AI20: 15 | AJ20: 15 | AL20: 15 | AM20: 15 | AN20: 15 | AO20: 15 | AP20: 15 | AQ20: 15 | AR20: 15 | AS20: 15 | AU20: 15 | AV20: 15 | AW20: 15
B21: 276 | C21: Descuento Comida Flex | D21: -200.1 | F21: -204.55 | H21: -219.95 | K21: -220 | S21: -184.3 | T21: -220 | V21: -191.46 | W21: -220 | X21: -27.22 | Z21: -31.6 | AD21: -158.94 | AE21: -20.3 | AF21: -202.58 | AG21: -54.13 | AK21: -123.87 | AL21: -107.29 | AN21: -1.85 | AO21: -49.9 | AP21: -14.7
B22: 277 | C22: Descuento Transp Flex | H22: -130.64 | S22: -20.45 | V22: -14 | Z22: -53.1 | AE22: -9.8 | AL22: -127 | AN22: -43.2 | AO22: -64.63 | AU22: -10
B23: 278 | C23: Descuento Guard Flex | F23: -372.67 | W23: -353.67 | AD23: -537.67
B24: 280 | C24: Descuento Seg Medico Fle | F24: -18.58 | T24: -18.58 | AE24: -9.29
B25: 283 | C25: Descuento Formacion Flex | Z25: -722.02
B26: 337 | C26: Comida Flex (Exenta) | D26: 200.1 | F26: 204.55 | H26: 219.95 | K26: 220 | S26: 184.3 | T26: 220 | V26: 191.46 | W26: 220 | X26: 27.22 | Z26: 31.6 | AD26: 158.94 | AE26: 20.3 | AF26: 202.58 | AG26: 54.13 | AK26: 123.87 | AL26: 107.29 | AN26: 1.85 | AO26: 49.9 | AP26: 14.7
B27: 338 | C27: Formación Flex (exento) | Z27: 722.02
B28: 339 | C28: Comida B. Social (Exent | E28: 167.15 | G28: 105.5 | I28: 220 | J28: 147.2 | L28: 194.81 | M28: 220 | N28: 218.05 | O28: 219.6 | Q28: 218.3 | R28: 120.46 | Y28: 56.35 | AA28: 144.97 | AC28: 47.29 | AG28: 42.91 | AH28: 60.83 | AI28: 137.76 | AJ28: 220 | AM28: 184.2 | AP28: 204.4
B29: 343 | C29: Transporte Flex (Exento) | H29: 130.64 | S29: 20.45 | V29: 14 | Z29: 53.1 | AE29: 9.8 | AL29: 127 | AN29: 43.2 | AO29: 64.63 | AU29: 10
B30: 345 | C30: Transporte B.S (Exento) | J30: 38.2 | N30: 86.3 | O30: 49.4 | P30: 43.2 | AC30: 41.2 | AH30: 3.3 | AJ30: 10 | AM30: 43.2 | AP30: 42.8 | AQ30: 9.6 | AV30: 32.7
B31: 349 | C31: Guarderia Flex (Exento) | F31: 372.67 | W31: 353.67 | AD31: 537.67
B32: 352 | C32: Seguro Salud Flex (Exent | F32: 18.58 | T32: 18.58 | AE32: 9.29
B33: 353 | C33: Seguro Médico B.S.(Exent | D33: 41.67 | E33: 83.34 | F33: 106.43 | H33: 41.67 | I33: 166.68 | J33: 41.67 | K33: 41.67 | M33: 83.34 | N33: 41.67 | O33: 41.67 | P33: 41.67 | Q33: 41.67 | R33: 41.67 | S33: 41.67 | T33: 106.43 | V33: 41.67 | W33: 41.67 | Y33: 41.67 | Z33: 41.67 | AB33: 125.01 | AC33: 41.67 | AE33: 32.38 | AJ33: 41.67
B34: 355 | C34: Seguro Salud Flex (No Ex | F34: 46.18 | T34: 46.18 | AE34: 23.09
B35: 356 | C35: Seguro Médico B.S. (No E | D35: 23.09 | E35: 46.18 | F35: 23.09 | H35: 23.09 | I35: 92.36 | J35: 23.09 | K35: 23.09 | M35: 46.18 | N35: 23.09 | O35: 23.09 | P35: 23.09 | Q35: 23.09 | R35: 23.09 | S35: 23.09 | T35: 23.09 | V35: 23.09 | W35: 23.09 | Y35: 23.09 | Z35: 23.09 | AB35: 69.27 | AC35: 23.09 | AJ35: 23.09
B36: 357 | C36: Descuento Seg flex (No e | F36: -46.18 | T36: -46.18 | AE36: -23.09
B37: 398 | C37: Plus Transporte | D37: 114.8 | E37: 137.76 | F37: 137.76 | G37: 137.76 | H37: 137.76 | I37: 137.76 | J37: 137.76 | K37: 133.06 | L37: 133.06 | M37: 137.76 | N37: 137.76 | O37: 137.76 | P37: 137.76 | Q37: 137.76 | R37: 137.76 | S37: 137.76 | T37: 137.76 | V37: 137.76 | W37: 137.76 | X37: 137.76 | Z37: 137.76 | AA37: 137.76 | AB37: 137.76 | AC37: 137.76 | AD37: 137.76 | AE37: 137.76 | AF37: 137.76 | AG37: 137.76 | AH37: 137.76 | AI37: 137.76 | AJ37: 137.76 | AK37: 110.21 | AL37: 137.76 | AM37: 137.76 | AN37: 137.76 | AO37: 137.76 | AP37: 137.76 | AQ37: 137.76 | AR37: 137.76 | AS37: 137.76 | AU37: 137.76 | AV37: 137.76 | AW37: 137.76 | AX37: 55.1
B38: 451 | C38: Enfermedad | Y38: 1886.35
B39: 988 | C39: Imp.Ingr. a Cta. Esp. Cg | D39: 4.61 | E39: 8.43 | F39: 11.64 | H39: 3.76 | I39: 30.46 | J39: 4.04 | K39: 4.28 | M39: 12.7 | N39: 3.81 | O39: 3.73 | P39: 3.69 | Q39: 4.43 | R39: 3.82 | S39: 3.58 | T39: 19.49 | V39: 3.77 | W39: 3.99 | Y39: 3.63 | Z39: 3.71 | AB39: 12.2 | AC39: 3.79 | AE39: 3.44 | AJ39: 2.65
A41: TOTAL BRUTO | D41: =SUM(D11:D40) -> 3220.48 | E41: =SUM(E11:E40) -> 3638.44 | F41: =SUM(F11:F40) -> 3156.17 | G41: =SUM(G11:G40) -> 2953.83 | H41: =SUM(H11:H40) -> 2583.53 | I41: =SUM(I11:I40) -> 9797.15 | J41: =SUM(J11:J40) -> 3019.21 | K41: =SUM(K11:K40) -> 3167.36 | ... AX41: =SUM(AX11:AX40) -> 706.74
B43: 789 | C43: Dcto.Conceptos en Especi | D43: 264.86 | E43: 296.67 | F43: 771.5 | G43: 105.5 | H43: 415.35 | I43: 479.04 | J43: 250.16 | K43: 284.76 | L43: 194.81 | M43: 349.52 | N43: 369.11 | O43: 333.76 | P43: 107.96 | Q43: 283.06 | R43: 185.22 | S43: 269.51 | T43: 414.28 | V43: 270.22 | W43: 638.43 | X43: 27.22 | Y43: 121.11 | Z43: 871.48 | AA43: 144.97 | AB43: 194.28 | AC43: 153.25 | AD43: 696.61 | AE43: 94.86 | AF43: 202.58 | AG43: 97.04 | AH43: 64.13 | AI43: 137.76 | AJ43: 294.76 | AK43: 123.87 | AL43: 234.29 | AM43: 227.4 | AN43: 45.05 | AO43: 114.53 | AP43: 261.9 | AQ43: 9.6 | AU43: 10 | AV43: 32.7
B44: 989 | C44: Imp.Ingr.a Cta.Valores E | D44: 4.61 | E44: 8.43 | F44: 11.64 | H44: 3.76 | I44: 30.46 | J44: 4.04 | K44: 4.28 | M44: 12.7 | N44: 3.81 | O44: 3.73 | P44: 3.69 | Q44: 4.43 | R44: 3.82 | S44: 3.58 | T44: 19.49 | V44: 3.77 | W44: 3.99 | Y44: 3.63 | Z44: 3.71 | AB44: 12.2 | AC44: 3.79 | AE44: 3.44 | AJ44: 2.65
B45: 995 | C45: COTIZACION CONT.COMUNES | D45: 155.97 | E45: 176.06 | F45: 152.51 | G45: 143.26 | H45: 125.12 | I45: 257.75 | J45: 146.23 | K45: 153.4 | L45: 171.84 | M45: 251.36 | N45: 139.88 | O45: 130.08 | P45: 139.34 | Q45: 192.29 | R45: 130.24 | S45: 117.04 | T45: 250.55 | V45: 125.12 | W45: 137.24 | X45: 134.11 | Y45: 118.04 | Z45: 125.12 | AA45: 120.93 | AB45: 143.53 | AC45: 129.41 | AD45: 113.89 | AE45: 109 | AF45: 126.02 | AG45: 140.63 | AH45: 100.84 | AI45: 104.41 | AJ45: 112.02 | AK45: 77.89 | AL45: 131.63 | AM45: 149.17 | AN45: 105.81 | AO45: 85.61 | AP45: 119.41 | AQ45: 114.36 | AR45: 85.61 | AS45: 85.6 | AU45: 85.61 | AV45: 87.58 | AW45: 94.09 | AX45: 34.28
...

Sheet 6
A2: Moneda: Euro | D2: 03 PLANNING CENTER
A3: PAGA TOTAL
A4: DEL 01/01/26 AL 31/01/26 | D4: TOTAL
A5: Empresa: 4008-DSD PLANNING CENTER S.L. NIF: B86563285 | D5: PLANNING CENTER
A9: CONCEPTO
B11: 1 | C11: Salario Base | D11: =SUM('5'!$D$11:$AY$11) -> 67164.8
B12: 3 | C12: Mejora Voluntaria | D12: =SUM('5'!$D$12:$AY$12) -> 33903.17
B13: 8 | C13: Plus Actividad | D13: =SUM('5'!$D$13:$AY$13) -> 8.13
B14: 51 | C14: Complemento Especialidad | D14: =SUM('5'!$D$14:$AY$14) -> 1100
B15: 53 | C15: Plus Nocturnidad | D15: =SUM('5'!$D$15:$AY$15) -> 825.01
B16: 63 | C16: Complemento de puesto te | D16: =SUM('5'!$D$16:$AY$16) -> 258.3
B17: 65 | C17: Complemento Puesto | D17: =SUM('5'!$D$17:$AY$17) -> 666.66
B18: 123 | C18: Prorrata PP. Extras | D18: =SUM('5'!$D$18:$AY$18) -> 11217.96
B19: 181 | C19: Plus Cumplimiento Objeti | D19: =SUM('5'!$D$19:$AY$19) -> 699
B20: 275 | C20: Teletrabajo | D20: =SUM('5'!$D$20:$AY$20) -> 615
B21: 276 | C21: Descuento Comida Flex | D21: =SUM('5'!$D$21:$AY$21) -> -2452.74
B22: 277 | C22: Descuento Transp Flex | D22: =SUM('5'!$D$22:$AY$22) -> -472.82
B23: 278 | C23: Descuento Guard Flex | D23: =SUM('5'!$D$23:$AY$23) -> -1264.01
B24: 280 | C24: Descuento Seg Medico Fle | D24: =SUM('5'!$D$24:$AY$24) -> -46.45
B25: 283 | C25: Descuento Formacion Flex | D25: =SUM('5'!$D$25:$AY$25) -> -722.02
B26: 337 | C26: Comida Flex (Exenta) | D26: =SUM('5'!$D$26:$AY$26) -> 2452.74
B27: 338 | C27: Formación Flex (exento) | D27: =SUM('5'!$D$27:$AY$27) -> 722.02
B28: 339 | C28: Comida B. Social (Exent | D28: =SUM('5'!$D$28:$AY$28) -> 2929.78
B29: 343 | C29: Transporte Flex (Exento) | D29: =SUM('5'!$D$29:$AY$29) -> 472.82
B30: 345 | C30: Transporte B.S (Exento) | D30: =SUM('5'!$D$30:$AY$30) -> 399.9
B31: 349 | C31: Guarderia Flex (Exento) | D31: =SUM('5'!$D$31:$AY$31) -> 1264.01
B32: 352 | C32: Seguro Salud Flex (Exent | D32: =SUM('5'!$D$32:$AY$32) -> 46.45
B33: 353 | C33: Seguro Médico B.S.(Exent | D33: =SUM('5'!$D$33:$AY$33) -> 1370.33
B34: 355 | C34: Seguro Salud Flex (No Ex | D34: =SUM('5'!$D$34:$AY$34) -> 115.45
B35: 356 | C35: Seguro Médico B.S. (No E | D35: =SUM('5'!$D$35:$AY$35) -> 669.61
B36: 357 | C36: Descuento Seg flex (No e | D36: =SUM('5'!$D$36:$AY$36) -> -115.45
B37: 398 | C37: Plus Transporte | D37: =SUM('5'!$D$37:$AY$37) -> 5918.87
B38: 451 | C38: Enfermedad | D38: =SUM('5'!$D$38:$AY$38) -> 1886.35
B39: 988 | C39: Imp.Ingr. a Cta. Esp. Cg | D39: =SUM('5'!$D$39:$AY$39) -> 159.65
A41: TOTAL BRUTO | D41: =SUM('5'!$D$41:$AY$41) -> 129792.52
B43: 789 | C43: Dcto.Conceptos en Especi | D43: =SUM('5'!$D$43:$AY$43) -> 10443.11
B44: 989 | C44: Imp.Ingr.a Cta.Valores E | D44: =SUM('5'!$D$44:$AY$44) -> 159.65
B45: 995 | C45: COTIZACION CONT.COMUNES | D45: =SUM('5'!$D$45:$AY$45) -> 5929.88
B46: 996 | C46: COTIZACION FORMACION PRO | D46: =SUM('5'!$D$46:$AY$46) -> 121.91
B47: 997 | C47: COTIZACION DESEMPLEO | D47: =SUM('5'!$D$47:$AY$47) -> 1889.56
...

Sheet 7
A2: Moneda: Euro | D2: 04 CORPORATE FUNCTIONS
A3: PAGA TOTAL
A4: DEL 01/01/26 AL 31/01/26 | D4: 000019 | E4: 000042 | F4: 000069 | G4: 000100 | H4: 000162 | I4: 000200
A5: Empresa: 4008-DSD PLANNING CENTER S.L. NIF: B86563285 | D5: HERNANDEZ | E5: GOUVEA | F5: EVANGELISTA | G5: CALLE | H5: MACDONALD | I5: SOLLA
D6: ALMELA | E6: AGRA | F6: VALERIA | G6: CUESTA | H6: BRENDON | I6: SANCHEZ
D7: SOFIA | E7: FERNANDO | F7: LORENA | G7: IRMA | I7: CARLOTA
A9: CONCEPTO
B11: 1 | C11: Salario Base | D11: 2000 | E11: 3500 | F11: 1122 | G11: 1800 | H11: 6000 | I11: 2000
B12: 3 | C12: Mejora Voluntaria | D12: 278.9 | E12: 2445.57 | F12: 553.93 | G12: 200.81 | H12: 3700.5 | I12: 862.24
B13: 8 | C13: Plus Actividad | F13: 91.43
B14: 123 | C14: Prorrata PP. Extras | D14: 333.34 | E14: 583.34 | F14: 187 | G14: 300 | H14: 1000 | I14: 333.34
B15: 275 | C15: Teletrabajo | D15: 15 | E15: 15 | F15: 15 | G15: 15 | H15: 15 | I15: 15
B16: 276 | C16: Descuento Comida Flex | H16: -220
B17: 277 | C17: Descuento Transp Flex | H17: -67.4
B18: 280 | C18: Descuento Seg Medico Fle | H18: -18.58
B19: 337 | C19: Comida Flex (Exenta) | H19: 220
B20: 339 | C20: Comida B. Social (Exent | D20: 220 | E20: 220 | F20: 220 | G20: 210.23 | I20: 169.91
B21: 343 | C21: Transporte Flex (Exento) | H21: 67.4
B22: 345 | C22: Transporte B.S (Exento) | D22: 49.2 | E22: 9.6 | F22: 38.2 | G22: 27.65 | I22: 7.3
B23: 352 | C23: Seguro Salud Flex (Exent | H23: 18.58
B24: 353 | C24: Seguro Médico B.S.(Exent | D24: 41.67 | E24: 41.67 | F24: 41.67 | G24: 41.67 | H24: 106.43 | I24: 41.67
B25: 355 | C25: Seguro Salud Flex (No Ex | H25: 46.18
B26: 356 | C26: Seguro Médico B.S. (No E | D26: 23.09 | E26: 23.09 | F26: 23.09 | G26: 23.09 | H26: 23.09 | I26: 23.09
B27: 357 | C27: Descuento Seg flex (No e | H27: -46.18
B28: 398 | C28: Plus Transporte | D28: 137.76 | E28: 137.76 | F28: 137.06 | G28: 99.19 | H28: 137.06 | I28: 137.76
B29: 988 | C29: Imp.Ingr. a Cta. Esp. Cg | D29: 4.03 | E29: 6.68 | F29: 3.13 | G29: 3.68 | H29: 24.02 | I29: 4.47
A31: TOTAL BRUTO | D31: =SUM(D11:D30) -> 3102.99 | E31: =SUM(E11:E30) -> 6982.71 | F31: =SUM(F11:F30) -> 2432.51 | G31: =SUM(G11:G30) -> 2721.32 | H31: =SUM(H11:H30) -> 11006.1 | I31: =SUM(I11:I30) -> 3594.78
B33: 789 | C33: Dcto.Conceptos en Especi | D33: 333.96 | E33: 294.36 | F33: 322.96 | G33: 302.64 | H33: 481.68 | I33: 241.97
B34: 989 | C34: Imp.Ingr.a Cta.Valores E | D34: 4.03 | E34: 6.68 | F34: 3.13 | G34: 3.68 | H34: 24.02 | I34: 4.47
B35: 995 | C35: COTIZACION CONT.COMUNES | D35: 150.3 | E35: 251.25 | F35: 117.82 | G35: 131.81 | H35: 260.66 | I35: 174.13
B36: 996 | C36: COTIZACION FORMACION PRO | D36: 3.1 | E36: 5.1 | F36: 2.43 | G36: 2.72 | H36: 5.1 | I36: 3.59
B37: 997 | C37: COTIZACION DESEMPLEO | D37: 48.03 | E37: 79.07 | F37: 37.66 | G37: 42.12 | H37: 79.07 | I37: 55.65
B38: 999 | C38: TRIBUTACION I.R.P.F. | D38: 483.05 | E38: 1933.01 | F38: 285.63 | G38: 384.71 | H38: 3640.49 | I38: 648.24
A40: TOTAL DEDUCCIONES | D40: =SUM(D32:D39) -> 1022.47 | E40: =SUM(E32:E39) -> 2569.47 | F40: =SUM(F32:F39) -> 769.63 | G40: =SUM(G32:G39) -> 867.68 | H40: =SUM(H32:H39) -> 4491.02 | I40: =SUM(I32:I39) -> 1128.05
A42: TOTAL LIQUIDO | D42: =(D31-D40) -> 2080.52 | E42: =(E31-E40) -> 4413.24 | F42: =(F31-F40) -> 1662.88 | G42: =(G31-G40) -> 1853.64 | H42: =(H31-H40) -> 6515.08 | I42: =(I31-I40) -> 2466.73
A43: PRORRATA PAGAS EXTRAS | D43: 0 | E43: 0 | F43: 0 | G43: 0 | H43: 0 | I43: 0
A44: SEGURIDAD SOCIAL EMPRESA | D44: 996.32 | E44: 1659.12 | F44: 781.05 | G44: 873.71 | H44: 1706.78 | I44: 1154.28
A45: SEGURIDAD SOCIAL TRABAJADOR | D45: 201.43 | E45: 335.42 | F45: 157.91 | G45: 176.65 | H45: 344.83 | I45: 233.37
A46: SEGURIDAD SOCIAL TOTAL | D46: 1197.75 | E46: 1994.54 | F46: 938.96 | G46: 1050.36 | H46: 2051.61 | I46: 1387.65
A47: COSTE COLAB. VOLUNTARIA | D47: 0 | E47: 0 | F47: 0 | G47: 0 | H47: 0 | I47: 0
...

Sheet 8
A2: Moneda: Euro | D2: 04 CORPORATE FUNCTIONS
A3: PAGA TOTAL
A4: DEL 01/01/26 AL 31/01/26 | D4: TOTAL
A5: Empresa: 4008-DSD PLANNING CENTER S.L. NIF: B86563285 | D5: CORPORATE FUNCTIONS
A9: CONCEPTO
B11: 1 | C11: Salario Base | D11: =SUM('7'!$D$11:$J$11) -> 16422
B12: 3 | C12: Mejora Voluntaria | D12: =SUM('7'!$D$12:$J$12) -> 8041.95
B13: 8 | C13: Plus Actividad | D13: =SUM('7'!$D$13:$J$13) -> 91.43
B14: 123 | C14: Prorrata PP. Extras | D14: =SUM('7'!$D$14:$J$14) -> 2737.02
B15: 275 | C15: Teletrabajo | D15: =SUM('7'!$D$15:$J$15) -> 90
B16: 276 | C16: Descuento Comida Flex | D16: =SUM('7'!$D$16:$J$16) -> -220
B17: 277 | C17: Descuento Transp Flex | D17: =SUM('7'!$D$17:$J$17) -> -67.4
B18: 280 | C18: Descuento Seg Medico Fle | D18: =SUM('7'!$D$18:$J$18) -> -18.58
B19: 337 | C19: Comida Flex (Exenta) | D19: =SUM('7'!$D$19:$J$19) -> 220
B20: 339 | C20: Comida B. Social (Exent | D20: =SUM('7'!$D$20:$J$20) -> 1040.14
B21: 343 | C21: Transporte Flex (Exento) | D21: =SUM('7'!$D$21:$J$21) -> 67.4
B22: 345 | C22: Transporte B.S (Exento) | D22: =SUM('7'!$D$22:$J$22) -> 131.95
B23: 352 | C23: Seguro Salud Flex (Exent | D23: =SUM('7'!$D$23:$J$23) -> 18.58
B24: 353 | C24: Seguro Médico B.S.(Exent | D24: =SUM('7'!$D$24:$J$24) -> 314.78
B25: 355 | C25: Seguro Salud Flex (No Ex | D25: =SUM('7'!$D$25:$J$25) -> 46.18
B26: 356 | C26: Seguro Médico B.S. (No E | D26: =SUM('7'!$D$26:$J$26) -> 138.54
B27: 357 | C27: Descuento Seg flex (No e | D27: =SUM('7'!$D$27:$J$27) -> -46.18
B28: 398 | C28: Plus Transporte | D28: =SUM('7'!$D$28:$J$28) -> 786.59
B29: 988 | C29: Imp.Ingr. a Cta. Esp. Cg | D29: =SUM('7'!$D$29:$J$29) -> 46.01
A31: TOTAL BRUTO | D31: =SUM('7'!$D$31:$J$31) -> 29840.41
B33: 789 | C33: Dcto.Conceptos en Especi | D33: =SUM('7'!$D$33:$J$33) -> 1977.57
B34: 989 | C34: Imp.Ingr.a Cta.Valores E | D34: =SUM('7'!$D$34:$J$34) -> 46.01
B35: 995 | C35: COTIZACION CONT.COMUNES | D35: =SUM('7'!$D$35:$J$35) -> 1085.97
B36: 996 | C36: COTIZACION FORMACION PRO | D36: =SUM('7'!$D$36:$J$36) -> 22.04
B37: 997 | C37: COTIZACION DESEMPLEO | D37: =SUM('7'!$D$37:$J$37) -> 341.6
B38: 999 | C38: TRIBUTACION I.R.P.F. | D38: =SUM('7'!$D$38:$J$38) -> 7375.13
A40: TOTAL DEDUCCIONES | D40: =SUM('7'!$D$40:$J$40) -> 10848.32
A42: TOTAL LIQUIDO | D42: =SUM('7'!$D$42:$J$42) -> 18992.09
A43: PRORRATA PAGAS EXTRAS | D43: =SUM('7'!$D$43:$J$43) -> 0
A44: SEGURIDAD SOCIAL EMPRESA | D44: =SUM('7'!$D$44:$J$44) -> 7171.26
A45: SEGURIDAD SOCIAL TRABAJADOR | D45: =SUM('7'!$D$45:$J$45) -> 1449.61
A46: SEGURIDAD SOCIAL TOTAL | D46: =SUM('7'!$D$46:$J$46) -> 8620.87
A47: COSTE COLAB. VOLUNTARIA | D47: =SUM('7'!$D$47:$J$47) -> 0
A48: APORTAC. SERVICIOS COMUNES | D48: =SUM('7'!$D$48:$J$48) -> 0
A49: COSTE EMPRESA | D49: =SUM('7'!$D$49:$J$49) -> 37011.67
...

Sheet 9
A2: Moneda: Euro | D2: 05 DELIGHT ROW
A3: PAGA TOTAL
A4: DEL 01/01/26 AL 31/01/26 | D4: 000011 | E4: 000158
A5: Empresa: 4008-DSD PLANNING CENTER S.L. NIF: B86563285 | D5: CABALLERO | E5: KURKA
D6: ESCOBAR | E6: BALTA
D7: CARMEN | E7: MARIA ELENA
A9: CONCEPTO
B11: 1 | C11: Salario Base | E11: 1100.76
B12: 3 | C12: Mejora Voluntaria | E12: 770.82
B13: 123 | C13: Prorrata PP. Extras | E13: 183.46
B14: 181 | C14: Plus Cumplimiento Objeti | E14: 1000
B15: 275 | C15: Teletrabajo | D15: 15 | E15: 15
B16: 339 | C16: Comida B. Social (Exent | E16: 177.8
B17: 345 | C17: Transporte B.S (Exento) | E17: 116.87
B18: 353 | C18: Seguro Médico B.S.(Exent | D18: 125.01
B19: 355 | C19: Seguro Salud Flex (No Ex | D19: 9.39
B20: 356 | C20: Seguro Médico B.S. (No E | D20: 59.88
B21: 357 | C21: Descuento Seg flex (No e | D21: -9.39
B22: 398 | C22: Plus Transporte | E22: 108.38
B23: 988 | C23: Imp.Ingr. a Cta. Esp. Cg | D23: 17.04
A25: TOTAL BRUTO | D25: =SUM(D11:D24) -> 216.93 | E25: =SUM(E11:E24) -> 3473.09
B27: 789 | C27: Dcto.Conceptos en Especi | D27: 194.28 | E27: 294.67
B28: 989 | C28: Imp.Ingr.a Cta.Valores E | D28: 17.04
B29: 995 | C29: COTIZACION CONT.COMUNES | E29: 168.45
B30: 996 | C30: COTIZACION FORMACION PRO | E30: 3.47
B31: 997 | C31: COTIZACION DESEMPLEO | E31: 53.83
B32: 999 | C32: TRIBUTACION I.R.P.F. | D32: 1.38 | E32: 491.7
A34: TOTAL DEDUCCIONES | D34: =SUM(D26:D33) -> 212.7 | E34: =SUM(E26:E33) -> 1012.12
A36: TOTAL LIQUIDO | D36: =(D25-D34) -> 4.23 | E36: =(E25-E34) -> 2460.97
A37: PRORRATA PAGAS EXTRAS | D37: 0 | E37: 0
A38: SEGURIDAD SOCIAL EMPRESA | D38: 1578.41 | E38: 1116.59
A39: SEGURIDAD SOCIAL TRABAJADOR | D39: 0 | E39: 225.75
A40: SEGURIDAD SOCIAL TOTAL | D40: 1578.41 | E40: 1342.34
A41: COSTE COLAB. VOLUNTARIA | D41: 0 | E41: 0
A42: APORTAC. SERVICIOS COMUNES | D42: 0 | E42: 0
A43: COSTE EMPRESA | D43: =D25+D38 -> 1795.34 | E43: =E25+E38 -> 4589.68
A44: BASE CONTINGENCIAS COMUNES | D44: 4909.5 | E44: 3473.09
A45: BASE ACCIDENTES | D45: 4909.5 | E45: 3473.09
A46: BASE I.R.P.F. DINERARIA | D46: 5.61 | E46: 3178.42
A47: BASE I.R.P.F. ESPECIES | D47: 69.27 | E47: 0
...

Sheet 10
A2: Moneda: Euro | D2: 05 DELIGHT ROW
A3: PAGA TOTAL
A4: DEL 01/01/26 AL 31/01/26 | D4: TOTAL
A5: Empresa: 4008-DSD PLANNING CENTER S.L. NIF: B86563285 | D5: DELIGHT ROW
A9: CONCEPTO
B11: 1 | C11: Salario Base | D11: =SUM('9'!$D$11:$F$11) -> 1100.76
B12: 3 | C12: Mejora Voluntaria | D12: =SUM('9'!$D$12:$F$12) -> 770.82
B13: 123 | C13: Prorrata PP. Extras | D13: =SUM('9'!$D$13:$F$13) -> 183.46
B14: 181 | C14: Plus Cumplimiento Objeti | D14: =SUM('9'!$D$14:$F$14) -> 1000
B15: 275 | C15: Teletrabajo | D15: =SUM('9'!$D$15:$F$15) -> 30
B16: 339 | C16: Comida B. Social (Exent | D16: =SUM('9'!$D$16:$F$16) -> 177.8
B17: 345 | C17: Transporte B.S (Exento) | D17: =SUM('9'!$D$17:$F$17) -> 116.87
B18: 353 | C18: Seguro Médico B.S.(Exent | D18: =SUM('9'!$D$18:$F$18) -> 125.01
B19: 355 | C19: Seguro Salud Flex (No Ex | D19: =SUM('9'!$D$19:$F$19) -> 9.39
B20: 356 | C20: Seguro Médico B.S. (No E | D20: =SUM('9'!$D$20:$F$20) -> 59.88
B21: 357 | C21: Descuento Seg flex (No e | D21: =SUM('9'!$D$21:$F$21) -> -9.39
B22: 398 | C22: Plus Transporte | D22: =SUM('9'!$D$22:$F$22) -> 108.38
B23: 988 | C23: Imp.Ingr. a Cta. Esp. Cg | D23: =SUM('9'!$D$23:$F$23) -> 17.04
A25: TOTAL BRUTO | D25: =SUM('9'!$D$25:$F$25) -> 3690.02
B27: 789 | C27: Dcto.Conceptos en Especi | D27: =SUM('9'!$D$27:$F$27) -> 488.95
B28: 989 | C28: Imp.Ingr.a Cta.Valores E | D28: =SUM('9'!$D$28:$F$28) -> 17.04
B29: 995 | C29: COTIZACION CONT.COMUNES | D29: =SUM('9'!$D$29:$F$29) -> 168.45
B30: 996 | C30: COTIZACION FORMACION PRO | D30: =SUM('9'!$D$30:$F$30) -> 3.47
B31: 997 | C31: COTIZACION DESEMPLEO | D31: =SUM('9'!$D$31:$F$31) -> 53.83
B32: 999 | C32: TRIBUTACION I.R.P.F. | D32: =SUM('9'!$D$32:$F$32) -> 493.08
A34: TOTAL DEDUCCIONES | D34: =SUM('9'!$D$34:$F$34) -> 1224.82
A36: TOTAL LIQUIDO | D36: =SUM('9'!$D$36:$F$36) -> 2465.2
A37: PRORRATA PAGAS EXTRAS | D37: =SUM('9'!$D$37:$F$37) -> 0
A38: SEGURIDAD SOCIAL EMPRESA | D38: =SUM('9'!$D$38:$F$38) -> 2695
A39: SEGURIDAD SOCIAL TRABAJADOR | D39: =SUM('9'!$D$39:$F$39) -> 225.75
A40: SEGURIDAD SOCIAL TOTAL | D40: =SUM('9'!$D$40:$F$40) -> 2920.75
A41: COSTE COLAB. VOLUNTARIA | D41: =SUM('9'!$D$41:$F$41) -> 0
A42: APORTAC. SERVICIOS COMUNES | D42: =SUM('9'!$D$42:$F$42) -> 0
A43: COSTE EMPRESA | D43: =SUM('9'!$D$43:$F$43) -> 6385.02
A44: BASE CONTINGENCIAS COMUNES | D44: =SUM('9'!$D$44:$F$44) -> 8382.59
A45: BASE ACCIDENTES | D45: =SUM('9'!$D$45:$F$45) -> 8382.59
A46: BASE I.R.P.F. DINERARIA | D46: =SUM('9'!$D$46:$F$46) -> 3184.03
A47: BASE I.R.P.F. ESPECIES | D47: =SUM('9'!$D$47:$F$47) -> 69.27
A48: BASE I.R.P.F. IRREGULAR | D48: =SUM('9'!$D$48:$F$48) -> 0
A49: HORAS EXTRAS NORMALES | D49: =SUM('9'!$D$49:$F$49) -> 0
...

Sheet 11
A2: Moneda: Euro | D2: 07 LAB
A3: PAGA TOTAL
A4: DEL 01/01/26 AL 31/01/26 | D4: 000086 | E4: 000109 | F4: 000169 | G4: 000172 | H4: 000198 | I4: 000213 | J4: 000216
A5: Empresa: 4008-DSD PLANNING CENTER S.L. NIF: B86563285 | D5: DE PABLOS | E5: GARCIA | F5: GONZALEZ | G5: TOSTE | H5: COIMBRA | I5: ANTELO | J5: ODYNTSOVA
D6: MOYA | E6: PEREZ | F6: SALAZAR | G6: COELHO | H6: SANDRA | I6: GIL | J6: ANNA
D7: JOSE MARIA | E7: ESTHER | F7: CARLOS ENRIQ | G7: SEGUNDO ANGE | H7: ISAAK PRATES | I7: ALBERTO
A9: CONCEPTO
B11: 1 | C11: Salario Base | D11: 1500 | E11: 2000 | F11: 1474.96 | G11: 5000 | H11: 2666.8 | I11: 583.81 | J11: 1167.63
B12: 3 | C12: Mejora Voluntaria | D12: 453.8 | E12: 862.24 | F12: 1191.45 | G12: 1974.91 | H12: 1250.98 | I12: 125 | J12: 250.01
B13: 8 | C13: Plus Actividad | E13: 263.1 | H13: 793.93
B14: 25 | C14: Plus Puntualidad | D14: 29.53
B15: 53 | C15: Plus Nocturnidad | F15: 250
B16: 123 | C16: Prorrata PP. Extras | D16: 250 | E16: 333.34 | F16: 245.82 | G16: 833.34 | H16: 444.46 | I16: 103.78 | J16: 194.6
B17: 273 | C17: Complemento Protesico | D17: 100
B18: 275 | C18: Teletrabajo | F18: 15
B19: 276 | C19: Descuento Comida Flex | D19: -95.6 | E19: -29.1 | H19: -220 | J19: -53.7
B20: 277 | C20: Descuento Transp Flex | D20: -101.5 | H20: -40.2 | J20: -10
B21: 278 | C21: Descuento Guard Flex | D21: -530
B22: 280 | C22: Descuento Seg Medico Fle | D22: -9.29 | G22: -9.29
B23: 337 | C23: Comida Flex (Exenta) | D23: 95.6 | E23: 29.1 | H23: 220 | J23: 53.7
B24: 339 | C24: Comida B. Social (Exent | F24: 214.27
B25: 343 | C25: Transporte Flex (Exento) | D25: 101.5 | H25: 40.2 | J25: 10
B26: 349 | C26: Guarderia Flex (Exento) | D26: 530
B27: 352 | C27: Seguro Salud Flex (Exent | D27: 9.29 | G27: 9.29
B28: 353 | C28: Seguro Médico B.S.(Exent | D28: 74.05 | E28: 41.67 | F28: 41.67 | G28: 32.38
B29: 355 | C29: Seguro Salud Flex (No Ex | D29: 23.09 | G29: 23.09
B30: 356 | C30: Seguro Médico B.S. (No E | D30: 23.09 | E30: 23.09 | F30: 23.09
B31: 357 | C31: Descuento Seg flex (No e | D31: -23.09 | G31: -23.09
B32: 398 | C32: Plus Transporte | E32: 137.76 | F32: 137.76 | G32: 137.76 | H32: 137.76 | I32: 68.88 | J32: 137.76
B33: 988 | C33: Imp.Ingr. a Cta. Esp. Cg | D33: 7.02 | E33: 4.73 | F33: 6 | G33: 7.29
A35: TOTAL BRUTO | D35: =SUM(D11:D34) -> 2437.49 | E35: =SUM(E11:E34) -> 3665.93 | F35: =SUM(F11:F34) -> 3600.02 | G35: =SUM(G11:G34) -> 7985.68 | H35: =SUM(H11:H34) -> 5293.93 | I35: =SUM(I11:I34) -> 881.47 | J35: =SUM(J11:J34) -> 1750
B37: 789 | C37: Dcto.Conceptos en Especi | D37: 856.62 | E37: 93.86 | F37: 279.03 | G37: 64.76 | H37: 260.2 | J37: 63.7
B38: 989 | C38: Imp.Ingr.a Cta.Valores E | D38: 7.02 | E38: 4.73 | F38: 6 | G38: 7.29
B39: 995 | C39: COTIZACION CONT.COMUNES | D39: 117.88 | E39: 177.57 | F39: 174.31 | G39: 253.45 | H39: 247.78 | I39: 42.75 | J39: 84.88
B40: 996 | C40: COTIZACION FORMACION PRO | D40: 2.43 | E40: 3.66 | F40: 3.59 | G40: 5.1 | H40: 5.1 | I40: 0.88 | J40: 1.75
B41: 997 | C41: COTIZACION DESEMPLEO | D41: 37.67 | E41: 56.75 | F41: 55.71 | G41: 79.07 | H41: 79.07 | I41: 13.66 | J41: 27.13
B42: 999 | C42: TRIBUTACION I.R.P.F. | D42: 239.23 | E42: 731.3 | F42: 861.9 | G42: 2499.92 | H42: 1226.72 | I42: 93.7 | J42: 187.35
A44: TOTAL DEDUCCIONES | D44: =SUM(D36:D43) -> 1260.85 | E44: =SUM(E36:E43) -> 1067.87 | F44: =SUM(F36:F43) -> 1380.54 | G44: =SUM(G36:G43) -> 2909.59 | H44: =SUM(H36:H43) -> 1818.87 | I44: =SUM(I36:I43) -> 150.99 | J44: =SUM(J36:J43) -> 364.81
A46: TOTAL LIQUIDO | D46: =(D35-D44) -> 1176.64 | E46: =(E35-E44) -> 2598.06 | F46: =(F35-F44) -> 2219.48 | G46: =(G35-G44) -> 5076.09 | H46: =(H35-H44) -> 3475.06 | I46: =(I35-I44) -> 730.48 | J46: =(J35-J44) -> 1385.19
A47: PRORRATA PAGAS EXTRAS | D47: 0 | E47: 0 | F47: 0 | G47: 0 | H47: 0 | I47: 0 | J47: 0
...

Sheet 12
A2: Moneda: Euro | D2: 07 LAB
A3: PAGA TOTAL
A4: DEL 01/01/26 AL 31/01/26 | D4: TOTAL | E4: TOTAL
A5: Empresa: 4008-DSD PLANNING CENTER S.L. NIF: B86563285 | D5: LAB | E5: DSD PLANNING CENTER S.L.
A9: CONCEPTO
B11: 1 | C11: Salario Base | D11: =SUM('11'!$D$11:$K$11) -> 14393.2 | E11: ='2'!$D$11+'4'!$D$11+'6'!$D$11+'8'!$D$11+'10'!$D$11+'12'!$D$11 -> 120631.89
B12: 3 | C12: Mejora Voluntaria | D12: =SUM('11'!$D$12:$K$12) -> 6108.39 | E12: ='12'!$D$12+'2'!$D$12+'4'!$D$12+'6'!$D$12+'8'!$D$12+'10'!$D$12 -> 56281.17
B13: 8 | C13: Plus Actividad | D13: =SUM('11'!$D$13:$K$13) -> 1057.03 | E13: ='12'!$D$13+'6'!$D$13+'8'!$D$13 -> 1156.59
B14: 25 | C14: Plus Puntualidad | D14: =SUM('11'!$D$14:$K$14) -> 29.53 | E14: ='12'!$D$14 -> 29.53
B15: 51 | C15: Complemento Especialidad | E15: ='6'!$D$14 -> 1100
B16: 53 | C16: Plus Nocturnidad | D16: =SUM('11'!$D$15:$K$15) -> 250 | E16: ='12'!$D$16+'6'!$D$15 -> 1075.01
B17: 63 | C17: Complemento de puesto te | E17: ='6'!$D$16 -> 258.3
B18: 65 | C18: Complemento Puesto | E18: ='6'!$D$17 -> 666.66
B19: 123 | C19: Prorrata PP. Extras | D19: =SUM('11'!$D$16:$K$16) -> 2405.34 | E19: ='12'!$D$19+'2'!$D$13+'4'!$D$13+'6'!$D$18+'8'!$D$14+'10'!$D$13 -> 20135.62
B20: 181 | C20: Plus Cumplimiento Objeti | E20: ='4'!$D$14+'6'!$D$19+'10'!$D$14 -> 2723.3
B21: 273 | C21: Complemento Protesico | D21: =SUM('11'!$D$17:$K$17) -> 100 | E21: ='12'!$D$21 -> 100
B22: 275 | C22: Teletrabajo | D22: =SUM('11'!$D$18:$K$18) -> 15 | E22: ='12'!$D$22+'2'!$D$14+'4'!$D$15+'6'!$D$20+'8'!$D$15+'10'!$D$15 -> 885
B23: 276 | C23: Descuento Comida Flex | D23: =SUM('11'!$D$19:$K$19) -> -398.4 | E23: ='12'!$D$23+'2'!$D$15+'4'!$D$16+'6'!$D$21+'8'!$D$16 -> -3999.65
B24: 277 | C24: Descuento Transp Flex | D24: =SUM('11'!$D$20:$K$20) -> -151.7 | E24: ='12'!$D$24+'4'!$D$17+'6'!$D$22+'8'!$D$17 -> -1007.73
B25: 278 | C25: Descuento Guard Flex | D25: =SUM('11'!$D$21:$K$21) -> -530 | E25: ='12'!$D$25+'6'!$D$23 -> -1794.01
B26: 280 | C26: Descuento Seg Medico Fle | D26: =SUM('11'!$D$22:$K$22) -> -18.58 | E26: ='12'!$D$26+'6'!$D$24+'8'!$D$18 -> -83.61
B27: 282 | C27: Vehículo Empresa | E27: ='4'!$D$18 -> 458.82
B28: 283 | C28: Descuento Formacion Flex | E28: ='6'!$D$25 -> -722.02
B29: 337 | C29: Comida Flex (Exenta) | D29: =SUM('11'!$D$23:$K$23) -> 398.4 | E29: ='12'!$D$29+'2'!$D$16+'4'!$D$19+'6'!$D$26+'8'!$D$19 -> 3999.65
B30: 338 | C30: Formación Flex (exento) | E30: ='6'!$D$27 -> 722.02
B31: 339 | C31: Comida B. Social (Exent | D31: =SUM('11'!$D$24:$K$24) -> 214.27 | E31: ='12'!$D$31+'4'!$D$20+'6'!$D$28+'8'!$D$20+'10'!$D$16 -> 4797.33
B32: 343 | C32: Transporte Flex (Exento) | D32: =SUM('11'!$D$25:$K$25) -> 151.7 | E32: ='12'!$D$32+'4'!$D$21+'6'!$D$29+'8'!$D$21 -> 1007.73
B33: 345 | C33: Transporte B.S (Exento) | E33: ='4'!$D$22+'6'!$D$30+'8'!$D$22+'10'!$D$17 -> 806.98
B34: 349 | C34: Guarderia Flex (Exento) | D34: =SUM('11'!$D$26:$K$26) -> 530 | E34: ='12'!$D$34+'6'!$D$31 -> 1794.01
B35: 352 | C35: Seguro Salud Flex (Exent | D35: =SUM('11'!$D$27:$K$27) -> 18.58 | E35: ='12'!$D$35+'6'!$D$32+'8'!$D$23 -> 83.61
B36: 353 | C36: Seguro Médico B.S.(Exent | D36: =SUM('11'!$D$28:$K$28) -> 189.77 | E36: ='12'!$D$36+'4'!$D$23+'6'!$D$33+'8'!$D$24+'10'!$D$18 -> 2208.24
B37: 355 | C37: Seguro Salud Flex (No Ex | D37: =SUM('11'!$D$29:$K$29) -> 46.18 | E37: ='12'!$D$37+'6'!$D$34+'8'!$D$25+'10'!$D$19 -> 217.2
B38: 356 | C38: Seguro Médico B.S. (No E | D38: =SUM('11'!$D$30:$K$30) -> 69.27 | E38: ='12'!$D$38+'4'!$D$24+'6'!$D$35+'8'!$D$26+'10'!$D$20 -> 1052.75
B39: 357 | C39: Descuento Seg flex (No e | D39: =SUM('11'!$D$31:$K$31) -> -46.18 | E39: ='12'!$D$39+'6'!$D$36+'8'!$D$27+'10'!$D$21 -> -217.2
B40: 398 | C40: Plus Transporte | D40: =SUM('11'!$D$32:$K$32) -> 757.68 | E40: ='12'!$D$40+'2'!$D$17+'4'!$D$25+'6'!$D$37+'8'!$D$28+'10'!$D$22 -> 8811.36
B41: 451 | C41: Enfermedad | E41: ='6'!$D$38 -> 1886.35
B42: 988 | C42: Imp.Ingr. a Cta. Esp. Cg | D42: =SUM('11'!$D$33:$K$33) -> 25.04 | E42: ='12'!$D$42+'4'!$D$26+'6'!$D$39+'8'!$D$29+'10'!$D$23 -> 387.49
A44: TOTAL BRUTO | D44: =SUM('11'!$D$35:$K$35) -> 25614.52 | E44: ='12'!$D$44+'2'!$D$19+'4'!$D$28+'6'!$D$41+'8'!$D$31+'10'!$D$25 -> 225452.39
B46: 768 | C46: Anticipo Paternidad | E46: ='4'!$D$30 -> 1119.4
B47: 789 | C47: Dcto.Conceptos en Especi | D47: =SUM('11'!$D$37:$K$37) -> 1618.17 | E47: ='12'!$D$47+'2'!$D$21+'4'!$D$31+'6'!$D$43+'8'!$D$33+'10'!$D$27 -> 17148.34
...
